<?xml version="1.0" encoding="UTF-8"?>
<testng-results skipped="0" failed="3" total="6" passed="3">
  <reporter-output>
  </reporter-output>
  <suite name="Default suite" duration-ms="71" started-at="2018-05-04T07:12:47Z" finished-at="2018-05-04T07:12:47Z">
    <groups>
    </groups>
    <test name="Default test" duration-ms="71" started-at="2018-05-04T07:12:47Z" finished-at="2018-05-04T07:12:47Z">
      <class name="org.testng.demo.SecondAppTest">
        <test-method status="FAIL" signature="firstNGTest()[pri:0, instance:org.testng.demo.SecondAppTest@7ac7a4e4]" name="firstNGTest" duration-ms="27" started-at="2018-05-04T12:42:47Z" finished-at="2018-05-04T12:42:47Z">
          <exception class="java.lang.AssertionError">
            <message>
              <![CDATA[This is TestNG-Maven Example 2 - test 1 : Fri May 04 12:42:47 IST 2018]]>
            </message>
            <full-stacktrace>
              <![CDATA[java.lang.AssertionError: This is TestNG-Maven Example 2 - test 1 : Fri May 04 12:42:47 IST 2018
	at org.testng.Assert.fail(Assert.java:94)
	at org.testng.demo.SecondAppTest.firstNGTest(SecondAppTest.java:14)
	at sun.reflect.NativeMethodAccessorImpl.invoke0(Native Method)
	at sun.reflect.NativeMethodAccessorImpl.invoke(NativeMethodAccessorImpl.java:62)
	at sun.reflect.DelegatingMethodAccessorImpl.invoke(DelegatingMethodAccessorImpl.java:43)
	at java.lang.reflect.Method.invoke(Method.java:498)
	at org.testng.internal.MethodInvocationHelper.invokeMethod(MethodInvocationHelper.java:84)
	at org.testng.internal.Invoker.invokeMethod(Invoker.java:714)
	at org.testng.internal.Invoker.invokeTestMethod(Invoker.java:901)
	at org.testng.internal.Invoker.invokeTestMethods(Invoker.java:1231)
	at org.testng.internal.TestMethodWorker.invokeTestMethods(TestMethodWorker.java:127)
	at org.testng.internal.TestMethodWorker.run(TestMethodWorker.java:111)
	at org.testng.TestRunner.privateRun(TestRunner.java:767)
	at org.testng.TestRunner.run(TestRunner.java:617)
	at org.testng.SuiteRunner.runTest(SuiteRunner.java:348)
	at org.testng.SuiteRunner.runSequentially(SuiteRunner.java:343)
	at org.testng.SuiteRunner.privateRun(SuiteRunner.java:305)
	at org.testng.SuiteRunner.run(SuiteRunner.java:254)
	at org.testng.SuiteRunnerWorker.runSuite(SuiteRunnerWorker.java:52)
	at org.testng.SuiteRunnerWorker.run(SuiteRunnerWorker.java:86)
	at org.testng.TestNG.runSuitesSequentially(TestNG.java:1224)
	at org.testng.TestNG.runSuitesLocally(TestNG.java:1149)
	at org.testng.TestNG.run(TestNG.java:1057)
	at org.testng.remote.AbstractRemoteTestNG.run(AbstractRemoteTestNG.java:114)
	at org.testng.remote.RemoteTestNG.initAndRun(RemoteTestNG.java:251)
	at org.testng.remote.RemoteTestNG.main(RemoteTestNG.java:77)
]]>
            </full-stacktrace>
          </exception> <!-- java.lang.AssertionError -->
          <reporter-output>
          </reporter-output>
        </test-method> <!-- firstNGTest -->
        <test-method status="PASS" signature="secondNGTest()[pri:0, instance:org.testng.demo.SecondAppTest@7ac7a4e4]" name="secondNGTest" duration-ms="2" started-at="2018-05-04T12:42:47Z" finished-at="2018-05-04T12:42:47Z">
          <reporter-output>
          </reporter-output>
        </test-method> <!-- secondNGTest -->
      </class> <!-- org.testng.demo.SecondAppTest -->
      <class name="org.testng.demo.ThirdAppTest">
        <test-method status="FAIL" signature="firstNGTest()[pri:0, instance:org.testng.demo.ThirdAppTest@548b7f67]" name="firstNGTest" duration-ms="1" started-at="2018-05-04T12:42:47Z" finished-at="2018-05-04T12:42:47Z">
          <exception class="java.lang.AssertionError">
            <message>
              <![CDATA[This is TestNG-Maven Example 3 - test 1 : Fri May 04 12:42:47 IST 2018]]>
            </message>
            <full-stacktrace>
              <![CDATA[java.lang.AssertionError: This is TestNG-Maven Example 3 - test 1 : Fri May 04 12:42:47 IST 2018
	at org.testng.Assert.fail(Assert.java:94)
	at org.testng.demo.ThirdAppTest.firstNGTest(ThirdAppTest.java:14)
	at sun.reflect.NativeMethodAccessorImpl.invoke0(Native Method)
	at sun.reflect.NativeMethodAccessorImpl.invoke(NativeMethodAccessorImpl.java:62)
	at sun.reflect.DelegatingMethodAccessorImpl.invoke(DelegatingMethodAccessorImpl.java:43)
	at java.lang.reflect.Method.invoke(Method.java:498)
	at org.testng.internal.MethodInvocationHelper.invokeMethod(MethodInvocationHelper.java:84)
	at org.testng.internal.Invoker.invokeMethod(Invoker.java:714)
	at org.testng.internal.Invoker.invokeTestMethod(Invoker.java:901)
	at org.testng.internal.Invoker.invokeTestMethods(Invoker.java:1231)
	at org.testng.internal.TestMethodWorker.invokeTestMethods(TestMethodWorker.java:127)
	at org.testng.internal.TestMethodWorker.run(TestMethodWorker.java:111)
	at org.testng.TestRunner.privateRun(TestRunner.java:767)
	at org.testng.TestRunner.run(TestRunner.java:617)
	at org.testng.SuiteRunner.runTest(SuiteRunner.java:348)
	at org.testng.SuiteRunner.runSequentially(SuiteRunner.java:343)
	at org.testng.SuiteRunner.privateRun(SuiteRunner.java:305)
	at org.testng.SuiteRunner.run(SuiteRunner.java:254)
	at org.testng.SuiteRunnerWorker.runSuite(SuiteRunnerWorker.java:52)
	at org.testng.SuiteRunnerWorker.run(SuiteRunnerWorker.java:86)
	at org.testng.TestNG.runSuitesSequentially(TestNG.java:1224)
	at org.testng.TestNG.runSuitesLocally(TestNG.java:1149)
	at org.testng.TestNG.run(TestNG.java:1057)
	at org.testng.remote.AbstractRemoteTestNG.run(AbstractRemoteTestNG.java:114)
	at org.testng.remote.RemoteTestNG.initAndRun(RemoteTestNG.java:251)
	at org.testng.remote.RemoteTestNG.main(RemoteTestNG.java:77)
]]>
            </full-stacktrace>
          </exception> <!-- java.lang.AssertionError -->
          <reporter-output>
          </reporter-output>
        </test-method> <!-- firstNGTest -->
        <test-method status="PASS" signature="secondNGTest()[pri:0, instance:org.testng.demo.ThirdAppTest@548b7f67]" name="secondNGTest" duration-ms="1" started-at="2018-05-04T12:42:47Z" finished-at="2018-05-04T12:42:47Z">
          <reporter-output>
          </reporter-output>
        </test-method> <!-- secondNGTest -->
      </class> <!-- org.testng.demo.ThirdAppTest -->
      <class name="org.testng.demo.FirstAppTest">
        <test-method status="FAIL" signature="firstNGTest()[pri:0, instance:org.testng.demo.FirstAppTest@2669b199]" name="firstNGTest" duration-ms="2" started-at="2018-05-04T12:42:47Z" finished-at="2018-05-04T12:42:47Z">
          <exception class="java.lang.AssertionError">
            <message>
              <![CDATA[This is TestNG-Maven Example 1 - test 1 : Fri May 04 12:42:47 IST 2018]]>
            </message>
            <full-stacktrace>
              <![CDATA[java.lang.AssertionError: This is TestNG-Maven Example 1 - test 1 : Fri May 04 12:42:47 IST 2018
	at org.testng.Assert.fail(Assert.java:94)
	at org.testng.demo.FirstAppTest.firstNGTest(FirstAppTest.java:14)
	at sun.reflect.NativeMethodAccessorImpl.invoke0(Native Method)
	at sun.reflect.NativeMethodAccessorImpl.invoke(NativeMethodAccessorImpl.java:62)
	at sun.reflect.DelegatingMethodAccessorImpl.invoke(DelegatingMethodAccessorImpl.java:43)
	at java.lang.reflect.Method.invoke(Method.java:498)
	at org.testng.internal.MethodInvocationHelper.invokeMethod(MethodInvocationHelper.java:84)
	at org.testng.internal.Invoker.invokeMethod(Invoker.java:714)
	at org.testng.internal.Invoker.invokeTestMethod(Invoker.java:901)
	at org.testng.internal.Invoker.invokeTestMethods(Invoker.java:1231)
	at org.testng.internal.TestMethodWorker.invokeTestMethods(TestMethodWorker.java:127)
	at org.testng.internal.TestMethodWorker.run(TestMethodWorker.java:111)
	at org.testng.TestRunner.privateRun(TestRunner.java:767)
	at org.testng.TestRunner.run(TestRunner.java:617)
	at org.testng.SuiteRunner.runTest(SuiteRunner.java:348)
	at org.testng.SuiteRunner.runSequentially(SuiteRunner.java:343)
	at org.testng.SuiteRunner.privateRun(SuiteRunner.java:305)
	at org.testng.SuiteRunner.run(SuiteRunner.java:254)
	at org.testng.SuiteRunnerWorker.runSuite(SuiteRunnerWorker.java:52)
	at org.testng.SuiteRunnerWorker.run(SuiteRunnerWorker.java:86)
	at org.testng.TestNG.runSuitesSequentially(TestNG.java:1224)
	at org.testng.TestNG.runSuitesLocally(TestNG.java:1149)
	at org.testng.TestNG.run(TestNG.java:1057)
	at org.testng.remote.AbstractRemoteTestNG.run(AbstractRemoteTestNG.java:114)
	at org.testng.remote.RemoteTestNG.initAndRun(RemoteTestNG.java:251)
	at org.testng.remote.RemoteTestNG.main(RemoteTestNG.java:77)
]]>
            </full-stacktrace>
          </exception> <!-- java.lang.AssertionError -->
          <reporter-output>
          </reporter-output>
        </test-method> <!-- firstNGTest -->
        <test-method status="PASS" signature="secondNGTest()[pri:0, instance:org.testng.demo.FirstAppTest@2669b199]" name="secondNGTest" duration-ms="3" started-at="2018-05-04T12:42:47Z" finished-at="2018-05-04T12:42:47Z">
          <reporter-output>
          </reporter-output>
        </test-method> <!-- secondNGTest -->
      </class> <!-- org.testng.demo.FirstAppTest -->
    </test> <!-- Default test -->
  </suite> <!-- Default suite -->
</testng-results>
